Workbook

Sheet Raw Dataset
A1: Employee ID | B1: Name | C1: Department | D1: Country | E1: Salary | F1: Date of Joining | G1: Performance Rating | H1: Gender | I1: Email
A2: EMP1000 | C2: Finance | E2: N/A | G2: 2 | H2: Unknown | I2: invalid_email
A3: EMP1001 | B3: Eve Adams | C3: HR | D3: Germany | E3: 54255 | F3: 42015 | G3: 1 | H3: Other | I3: user106@example.com
A4: EMP1002 | B4: Alice Brown | C4: Finance | D4: Germany | E4: 63184 | F4: 42022 | G4: 2 | I4: user176@example.com
A5: EMP1003 | B5: John Doe | C5: Sales | D5: USA | E5: 94406 | F5: 42029 | G5: 1 | H5: Male | I5: user168@example.com
A6: EMP1004 | B6: Jane Smith | C6: Sales | D6: Germany | E6: 64120 | F6: 42036 | G6: 1 | H6: Male | I6: user49@example.com
A7: EMP1005 | B7: Alice Brown | C7: IT | D7: India | E7: 78421 | F7: 42043 | G7: 2 | H7: Female | I7: user24@example.com
A8: EMP1006 | B8: Sam Wilson | C8: Sales | E8: 67721 | F8: 42050 | H8: Male | I8: user168@example.com
A9: EMP1007 | B9: Chris Lee | C9: Marketing | E9: 35364 | F9: 42057 | G9: 2 | H9: Other | I9: user26@example.com
A10: EMP1008 | B10: Alice Brown | C10: IT | D10: Germany | E10: 97881 | F10: 42064 | H10: Female | I10: user25@example.com
A11: EMP1009 | B11: Chris Lee | C11: HR | D11: UK | E11: 91846 | F11: 42071 | H11: Male | I11: user153@example.com
A12: EMP1010 | B12: Sam Wilson | C12: Finance | D12: UK | E12: 64247 | F12: 42078 | G12: 1 | H12: Female | I12: user18@example.com
A13: EMP1011 | B13: Sam Wilson | C13: IT | D13: USA | E13: 91180 | F13: 42085 | G13: 5 | H13: Male | I13: user1@example.com
A14: EMP1012 | B14: Bob Johnson | C14: Sales | E14: 96418 | F14: 42092 | G14: 5 | H14: Male | I14: user106@example.com
A15: EMP1013 | B15: Sam Wilson | D15: India | E15: 62158 | F15: 42099 | G15: 4 | I15: user180@example.com
A16: EMP1014 | B16: Jane Smith | C16: HR | E16: 59894 | F16: 42106 | G16: 2 | H16: Male | I16: user184@example.com
A17: EMP1015 | C17: IT | D17: India | E17: 92443 | F17: 42113 | G17: 3 | H17: Other | I17: user3@example.com
A18: EMP1016 | B18: Bob Johnson | D18: Germany | E18: 90271 | F18: 42120 | I18: user64@example.com
A19: EMP1017 | B19: Jane Smith | C19: Finance | D19: Australia | E19: 41341 | F19: 42127 | G19: 1 | H19: Other | I19: user38@example.com
A20: EMP1018 | B20: Alice Brown | C20: Finance | D20: UK | E20: 73602 | F20: 42134 | I20: user96@example.com
A21: EMP1019 | B21: Eve Adams | D21: India | E21: 67531 | F21: 42141 | G21: 5 | H21: Female | I21: user151@example.com
A22: EMP1020 | B22: Jane Smith | C22: HR | D22: USA | E22: N/A | F22: 42148 | G22: 2 | H22: Other | I22: user200@example.com
A23: EMP1021 | B23: Jane Smith | C23: HR | E23: 98922 | F23: 42155 | G23: 4 | I23: user77@example.com
A24: EMP1022 | B24: Eve Adams | C24: Finance | D24: India | E24: 38333 | F24: 42162 | G24: 5 | I24: user128@example.com
A25: EMP1023 | B25: Alice Brown | C25: Marketing | D25: UK | E25: 36515 | F25: 42169 | G25: 3 | H25: Male | I25: user149@example.com
A26: EMP1024 | B26: Sam Wilson | C26: Finance | E26: 91005 | F26: 42176 | G26: 1 | H26: Other | I26: user122@example.com
A27: EMP1025 | B27: Chris Lee | E27: 52272 | F27: 42183 | G27: 3 | I27: user41@example.com
A28: EMP1026 | B28: Eve Adams | C28: Sales | D28: Germany | E28: 76518 | F28: 42190 | G28: 2 | H28: Female | I28: user68@example.com
A29: EMP1027 | B29: Alice Brown | C29: IT | D29: UK | E29: 41448 | F29: 42197 | G29: 3 | H29: Other | I29: user103@example.com
A30: EMP1028 | B30: John Doe | C30: HR | D30: UK | E30: 49282 | F30: 42204 | G30: 2 | H30: Female | I30: user135@example.com
A31: EMP1029 | B31: Bob Johnson | C31: Marketing | D31: UK | E31: 92959 | F31: 42211 | G31: 5 | I31: user83@example.com
A32: EMP1030 | C32: Marketing | E32: 92259 | G32: 1 | H32: Unknown | I32: user109@example.com
A33: EMP1031 | B33: Eve Adams | C33: HR | D33: Germany | E33: 92299 | F33: 42225 | G33: 3 | H33: Male | I33: user143@example.com
A34: EMP1032 | B34: Sam Wilson | C34: HR | E34: 95586 | F34: 42232 | G34: 3 | H34: Other | I34: user190@example.com
A35: EMP1033 | B35: Chris Lee | D35: USA | E35: 95367 | F35: 42239 | H35: Male | I35: user136@example.com
A36: EMP1034 | B36: John Doe | C36: Sales | D36: Australia | E36: 79549 | F36: 42246 | G36: 3 | I36: user198@example.com
A37: EMP1035 | B37: Alice Brown | D37: UK | E37: 54463 | F37: 42253 | G37: 4 | H37: Male | I37: invalid_email
A38: EMP1036 | B38: Alice Brown | C38: IT | D38: USA | E38: 89781 | F38: 42260 | H38: Female | I38: user31@example.com
A39: EMP1037 | B39: Alice Brown | C39: HR | E39: 64796 | F39: 42267 | H39: Other | I39: user98@example.com
A40: EMP1038 | B40: John Doe | C40: Marketing | D40: UK | E40: 52093 | F40: 42274 | G40: 5 | I40: user154@example.com
...

Sheet Day-1-Clean Dataset
A1: Employee ID | B1: Name | C1: Department | D1: Country | E1: Salary | F1: Date of Joining | G1: Performance Rating | H1: Gender | I1: Email
A2: EMP1000 | C2: Finance | E2: N/A | G2: 2 | H2: Unknown | I2: invalid_email
A3: EMP1001 | B3: Eve Adams | C3: HR | D3: Germany | E3: 54255 | F3: 42015 | G3: 1 | H3: Other | I3: user106@example.com
A4: EMP1002 | B4: Alice Brown | C4: Finance | D4: Germany | E4: 63184 | F4: 42022 | G4: 2 | I4: user176@example.com
A5: EMP1003 | B5: John Doe | C5: Sales | D5: USA | E5: 94406 | F5: 42029 | G5: 1 | H5: Male | I5: user168@example.com
A6: EMP1004 | B6: Jane Smith | C6: Sales | D6: Germany | E6: 64120 | F6: 42036 | G6: 1 | H6: Male | I6: user49@example.com
A7: EMP1005 | B7: Alice Brown | C7: IT | D7: India | E7: 78421 | F7: 42043 | G7: 2 | H7: Female | I7: user24@example.com
A8: EMP1006 | B8: Sam Wilson | C8: Sales | E8: 67721 | F8: 42050 | H8: Male | I8: user168@example.com
A9: EMP1007 | B9: Chris Lee | C9: Marketing | E9: 35364 | F9: 42057 | G9: 2 | H9: Other | I9: user26@example.com
A10: EMP1008 | B10: Alice Brown | C10: IT | D10: Germany | E10: 97881 | F10: 42064 | H10: Female | I10: user25@example.com
A11: EMP1009 | B11: Chris Lee | C11: HR | D11: UK | E11: 91846 | F11: 42071 | H11: Male | I11: user153@example.com
A12: EMP1010 | B12: Sam Wilson | C12: Finance | D12: UK | E12: 64247 | F12: 42078 | G12: 1 | H12: Female | I12: user18@example.com
A13: EMP1011 | B13: Sam Wilson | C13: IT | D13: USA | E13: 91180 | F13: 42085 | G13: 5 | H13: Male | I13: user1@example.com
A14: EMP1012 | B14: Bob Johnson | C14: Sales | E14: 96418 | F14: 42092 | G14: 5 | H14: Male | I14: user106@example.com
A15: EMP1013 | B15: Sam Wilson | D15: India | E15: 62158 | F15: 42099 | G15: 4 | I15: user180@example.com
A16: EMP1014 | B16: Jane Smith | C16: HR | E16: 59894 | F16: 42106 | G16: 2 | H16: Male | I16: user184@example.com
A17: EMP1015 | C17: IT | D17: India | E17: 92443 | F17: 42113 | G17: 3 | H17: Other | I17: user3@example.com
A18: EMP1016 | B18: Bob Johnson | D18: Germany | E18: 90271 | F18: 42120 | I18: user64@example.com
A19: EMP1017 | B19: Jane Smith | C19: Finance | D19: Australia | E19: 41341 | F19: 42127 | G19: 1 | H19: Other | I19: user38@example.com
A20: EMP1018 | B20: Alice Brown | C20: Finance | D20: UK | E20: 73602 | F20: 42134 | I20: user96@example.com
A21: EMP1019 | B21: Eve Adams | D21: India | E21: 67531 | F21: 42141 | G21: 5 | H21: Female | I21: user151@example.com
A22: EMP1020 | B22: Jane Smith | C22: HR | D22: USA | E22: N/A | F22: 42148 | G22: 2 | H22: Other | I22: user200@example.com
A23: EMP1021 | B23: Jane Smith | C23: HR | E23: 98922 | F23: 42155 | G23: 4 | I23: user77@example.com
A24: EMP1022 | B24: Eve Adams | C24: Finance | D24: India | E24: 38333 | F24: 42162 | G24: 5 | I24: user128@example.com
A25: EMP1023 | B25: Alice Brown | C25: Marketing | D25: UK | E25: 36515 | F25: 42169 | G25: 3 | H25: Male | I25: user149@example.com
A26: EMP1024 | B26: Sam Wilson | C26: Finance | E26: 91005 | F26: 42176 | G26: 1 | H26: Other | I26: user122@example.com
A27: EMP1025 | B27: Chris Lee | E27: 52272 | F27: 42183 | G27: 3 | I27: user41@example.com
A28: EMP1026 | B28: Eve Adams | C28: Sales | D28: Germany | E28: 76518 | F28: 42190 | G28: 2 | H28: Female | I28: user68@example.com
A29: EMP1027 | B29: Alice Brown | C29: IT | D29: UK | E29: 41448 | F29: 42197 | G29: 3 | H29: Other | I29: user103@example.com
A30: EMP1028 | B30: John Doe | C30: HR | D30: UK | E30: 49282 | F30: 42204 | G30: 2 | H30: Female | I30: user135@example.com
A31: EMP1029 | B31: Bob Johnson | C31: Marketing | D31: UK | E31: 92959 | F31: 42211 | G31: 5 | I31: user83@example.com
A32: EMP1030 | C32: Marketing | E32: 92259 | G32: 1 | H32: Unknown | I32: user109@example.com
A33: EMP1031 | B33: Eve Adams | C33: HR | D33: Germany | E33: 92299 | F33: 42225 | G33: 3 | H33: Male | I33: user143@example.com
A34: EMP1032 | B34: Sam Wilson | C34: HR | E34: 95586 | F34: 42232 | G34: 3 | H34: Other | I34: user190@example.com
A35: EMP1033 | B35: Chris Lee | D35: USA | E35: 95367 | F35: 42239 | H35: Male | I35: user136@example.com
A36: EMP1034 | B36: John Doe | C36: Sales | D36: Australia | E36: 79549 | F36: 42246 | G36: 3 | I36: user198@example.com
A37: EMP1035 | B37: Alice Brown | D37: UK | E37: 54463 | F37: 42253 | G37: 4 | H37: Male | I37: invalid_email
A38: EMP1036 | B38: Alice Brown | C38: IT | D38: USA | E38: 89781 | F38: 42260 | H38: Female | I38: user31@example.com
A39: EMP1037 | B39: Alice Brown | C39: HR | E39: 64796 | F39: 42267 | H39: Other | I39: user98@example.com
A40: EMP1038 | B40: John Doe | C40: Marketing | D40: UK | E40: 52093 | F40: 42274 | G40: 5 | I40: user154@example.com
...

Sheet Day 1 Observations
H4: Day 1 – Dataset Selection & Import
G5: No. | H5: Observation
G6: 1 | H6: The dataset contains 150 employee records and 9 columns.
G7: 2 | H7: The dataset contains different data types, including text, numerical values, and dates.
G8: 3 | H8: Important fields include Employee ID, Name, Department, Country, Salary, Date of Joining, Performance Rating, Gender, and Email. | K8: s
G9: 4 | H9: Some fields contain missing or blank values, which may need to be handled during later data-cleaning stages.

Sheet Day-2 Clean Dataset
A1: Employee ID | B1: Name | C1: Department | D1: Country | E1: Salary | F1: Date of Joining | G1: Performance Rating | H1: Gender | I1: Email
A2: EMP1000 | C2: Finance | E2: N/A | G2: 2 | H2: Unknown | I2: invalid_email
A3: EMP1001 | B3: Eve Adams | C3: HR | D3: Germany | E3: 54255 | F3: 42015 | G3: 1 | H3: Other | I3: user106@example.com
A4: EMP1002 | B4: Alice Brown | C4: Finance | D4: Germany | E4: 63184 | F4: 42022 | G4: 2 | I4: user176@example.com
A5: EMP1003 | B5: John Doe | C5: Sales | D5: USA | E5: 94406 | F5: 42029 | G5: 1 | H5: Male | I5: user168@example.com
A6: EMP1004 | B6: Jane Smith | C6: Sales | D6: Germany | E6: 64120 | F6: 42036 | G6: 1 | H6: Male | I6: user49@example.com
A7: EMP1005 | B7: Alice Brown | C7: IT | D7: India | E7: 78421 | F7: 42043 | G7: 2 | H7: Female | I7: user24@example.com
A8: EMP1006 | B8: Sam Wilson | C8: Sales | E8: 67721 | F8: 42050 | H8: Male | I8: user168@example.com
A9: EMP1007 | B9: Chris Lee | C9: Marketing | E9: 35364 | F9: 42057 | G9: 2 | H9: Other | I9: user26@example.com
A10: EMP1008 | B10: Alice Brown | C10: IT | D10: Germany | E10: 97881 | F10: 42064 | H10: Female | I10: user25@example.com
A11: EMP1009 | B11: Chris Lee | C11: HR | D11: UK | E11: 91846 | F11: 42071 | H11: Male | I11: user153@example.com
A12: EMP1010 | B12: Sam Wilson | C12: Finance | D12: UK | E12: 64247 | F12: 42078 | G12: 1 | H12: Female | I12: user18@example.com
A13: EMP1011 | B13: Sam Wilson | C13: IT | D13: USA | E13: 91180 | F13: 42085 | G13: 5 | H13: Male | I13: user1@example.com
A14: EMP1012 | B14: Bob Johnson | C14: Sales | E14: 96418 | F14: 42092 | G14: 5 | H14: Male | I14: user106@example.com
A15: EMP1013 | B15: Sam Wilson | D15: India | E15: 62158 | F15: 42099 | G15: 4 | I15: user180@example.com
A16: EMP1014 | B16: Jane Smith | C16: HR | E16: 59894 | F16: 42106 | G16: 2 | H16: Male | I16: user184@example.com
A17: EMP1015 | C17: IT | D17: India | E17: 92443 | F17: 42113 | G17: 3 | H17: Other | I17: user3@example.com
A18: EMP1016 | B18: Bob Johnson | D18: Germany | E18: 90271 | F18: 42120 | I18: user64@example.com
A19: EMP1017 | B19: Jane Smith | C19: Finance | D19: Australia | E19: 41341 | F19: 42127 | G19: 1 | H19: Other | I19: user38@example.com
A20: EMP1018 | B20: Alice Brown | C20: Finance | D20: UK | E20: 73602 | F20: 42134 | I20: user96@example.com
A21: EMP1019 | B21: Eve Adams | D21: India | E21: 67531 | F21: 42141 | G21: 5 | H21: Female | I21: user151@example.com
A22: EMP1020 | B22: Jane Smith | C22: HR | D22: USA | E22: N/A | F22: 42148 | G22: 2 | H22: Other | I22: user200@example.com
A23: EMP1021 | B23: Jane Smith | C23: HR | E23: 98922 | F23: 42155 | G23: 4 | I23: user77@example.com
A24: EMP1022 | B24: Eve Adams | C24: Finance | D24: India | E24: 38333 | F24: 42162 | G24: 5 | I24: user128@example.com
A25: EMP1023 | B25: Alice Brown | C25: Marketing | D25: UK | E25: 36515 | F25: 42169 | G25: 3 | H25: Male | I25: user149@example.com
A26: EMP1024 | B26: Sam Wilson | C26: Finance | E26: 91005 | F26: 42176 | G26: 1 | H26: Other | I26: user122@example.com
A27: EMP1025 | B27: Chris Lee | E27: 52272 | F27: 42183 | G27: 3 | I27: user41@example.com
A28: EMP1026 | B28: Eve Adams | C28: Sales | D28: Germany | E28: 76518 | F28: 42190 | G28: 2 | H28: Female | I28: user68@example.com
A29: EMP1027 | B29: Alice Brown | C29: IT | D29: UK | E29: 41448 | F29: 42197 | G29: 3 | H29: Other | I29: user103@example.com
A30: EMP1028 | B30: John Doe | C30: HR | D30: UK | E30: 49282 | F30: 42204 | G30: 2 | H30: Female | I30: user135@example.com
A31: EMP1029 | B31: Bob Johnson | C31: Marketing | D31: UK | E31: 92959 | F31: 42211 | G31: 5 | I31: user83@example.com
A32: EMP1030 | C32: Marketing | E32: 92259 | G32: 1 | H32: Unknown | I32: user109@example.com
A33: EMP1031 | B33: Eve Adams | C33: HR | D33: Germany | E33: 92299 | F33: 42225 | G33: 3 | H33: Male | I33: user143@example.com
A34: EMP1032 | B34: Sam Wilson | C34: HR | E34: 95586 | F34: 42232 | G34: 3 | H34: Other | I34: user190@example.com
A35: EMP1033 | B35: Chris Lee | D35: USA | E35: 95367 | F35: 42239 | H35: Male | I35: user136@example.com
A36: EMP1034 | B36: John Doe | C36: Sales | D36: Australia | E36: 79549 | F36: 42246 | G36: 3 | I36: user198@example.com
A37: EMP1035 | B37: Alice Brown | D37: UK | E37: 54463 | F37: 42253 | G37: 4 | H37: Male | I37: invalid_email
A38: EMP1036 | B38: Alice Brown | C38: IT | D38: USA | E38: 89781 | F38: 42260 | H38: Female | I38: user31@example.com
A39: EMP1037 | B39: Alice Brown | C39: HR | E39: 64796 | F39: 42267 | H39: Other | I39: user98@example.com
A40: EMP1038 | B40: John Doe | C40: Marketing | D40: UK | E40: 52093 | F40: 42274 | G40: 5 | I40: user154@example.com
...

Sheet Day-2 Observations
G3: Day 2 – Data Entry & Formatting
F4: No. | G4: Observation
F5: 1 | G5: The header row was formatted using bold text, background color, and center alignment.
F6: 2 | G6: Row and column insertion and deletion were practiced without changing the employee data.
F7: 3 | G7: Column widths were adjusted to make the employee information easier to read.
F8: 4 | G8: The dataset was organized and formatted to improve readability for further analysis.

Sheet Day-3 Clean Dataset
A1: Employee ID | B1: Name | C1: Department | D1: Country | E1: Salary | F1: Date of Joining | G1: Performance Rating | H1: Gender | I1: Email | J1: Metric | K1: Salary | L1: Performance Rating
A2: EMP1000 | C2: Finance | E2: N/A | G2: 2 | H2: Unknown | I2: invalid_email | J2: Total Salary | K2: =SUM(E:E) -> 9411892 | L2: =SUM(G:G) -> 359
A3: EMP1001 | B3: Eve Adams | C3: HR | D3: Germany | E3: 54255 | F3: 42015 | G3: 1 | H3: Other | I3: user106@example.com | J3: Average Salary | K3: =AVERAGE(E:E) -> 66280.93 | L3: =AVERAGE(G:G) -> 2.872
A4: EMP1002 | B4: Alice Brown | C4: Finance | D4: Germany | E4: 63184 | F4: 42022 | G4: 2 | I4: user176@example.com | J4: Minimum Salary | K4: =MIN(E:E) -> 30280 | L4: =MIN(G:G) -> 1
A5: EMP1003 | B5: John Doe | C5: Sales | D5: USA | E5: 94406 | F5: 42029 | G5: 1 | H5: Male | I5: user168@example.com | J5: Maximum Salary | K5: =MAX(E:E) -> 99621 | L5: =MAX(G:G) -> 5
A6: EMP1004 | B6: Jane Smith | C6: Sales | D6: Germany | E6: 64120 | F6: 42036 | G6: 1 | H6: Male | I6: user49@example.com | J6: Count Salary | K6: =COUNT(E:E) -> 142 | L6: =COUNT(G:G) -> 125
A7: EMP1005 | B7: Alice Brown | C7: IT | D7: India | E7: 78421 | F7: 42043 | G7: 2 | H7: Female | I7: user24@example.com
A8: EMP1006 | B8: Sam Wilson | C8: Sales | E8: 67721 | F8: 42050 | H8: Male | I8: user168@example.com
A9: EMP1007 | B9: Chris Lee | C9: Marketing | E9: 35364 | F9: 42057 | G9: 2 | H9: Other | I9: user26@example.com
A10: EMP1008 | B10: Alice Brown | C10: IT | D10: Germany | E10: 97881 | F10: 42064 | H10: Female | I10: user25@example.com
A11: EMP1009 | B11: Chris Lee | C11: HR | D11: UK | E11: 91846 | F11: 42071 | H11: Male | I11: user153@example.com
A12: EMP1010 | B12: Sam Wilson | C12: Finance | D12: UK | E12: 64247 | F12: 42078 | G12: 1 | H12: Female | I12: user18@example.com
A13: EMP1011 | B13: Sam Wilson | C13: IT | D13: USA | E13: 91180 | F13: 42085 | G13: 5 | H13: Male | I13: user1@example.com
A14: EMP1012 | B14: Bob Johnson | C14: Sales | E14: 96418 | F14: 42092 | G14: 5 | H14: Male | I14: user106@example.com
A15: EMP1013 | B15: Sam Wilson | D15: India | E15: 62158 | F15: 42099 | G15: 4 | I15: user180@example.com
A16: EMP1014 | B16: Jane Smith | C16: HR | E16: 59894 | F16: 42106 | G16: 2 | H16: Male | I16: user184@example.com
A17: EMP1015 | C17: IT | D17: India | E17: 92443 | F17: 42113 | G17: 3 | H17: Other | I17: user3@example.com
A18: EMP1016 | B18: Bob Johnson | D18: Germany | E18: 90271 | F18: 42120 | I18: user64@example.com
A19: EMP1017 | B19: Jane Smith | C19: Finance | D19: Australia | E19: 41341 | F19: 42127 | G19: 1 | H19: Other | I19: user38@example.com
A20: EMP1018 | B20: Alice Brown | C20: Finance | D20: UK | E20: 73602 | F20: 42134 | I20: user96@example.com
A21: EMP1019 | B21: Eve Adams | D21: India | E21: 67531 | F21: 42141 | G21: 5 | H21: Female | I21: user151@example.com
A22: EMP1020 | B22: Jane Smith | C22: HR | D22: USA | E22: N/A | F22: 42148 | G22: 2 | H22: Other | I22: user200@example.com
A23: EMP1021 | B23: Jane Smith | C23: HR | E23: 98922 | F23: 42155 | G23: 4 | I23: user77@example.com
A24: EMP1022 | B24: Eve Adams | C24: Finance | D24: India | E24: 38333 | F24: 42162 | G24: 5 | I24: user128@example.com
A25: EMP1023 | B25: Alice Brown | C25: Marketing | D25: UK | E25: 36515 | F25: 42169 | G25: 3 | H25: Male | I25: user149@example.com
A26: EMP1024 | B26: Sam Wilson | C26: Finance | E26: 91005 | F26: 42176 | G26: 1 | H26: Other | I26: user122@example.com
A27: EMP1025 | B27: Chris Lee | E27: 52272 | F27: 42183 | G27: 3 | I27: user41@example.com
A28: EMP1026 | B28: Eve Adams | C28: Sales | D28: Germany | E28: 76518 | F28: 42190 | G28: 2 | H28: Female | I28: user68@example.com
A29: EMP1027 | B29: Alice Brown | C29: IT | D29: UK | E29: 41448 | F29: 42197 | G29: 3 | H29: Other | I29: user103@example.com
A30: EMP1028 | B30: John Doe | C30: HR | D30: UK | E30: 49282 | F30: 42204 | G30: 2 | H30: Female | I30: user135@example.com
A31: EMP1029 | B31: Bob Johnson | C31: Marketing | D31: UK | E31: 92959 | F31: 42211 | G31: 5 | I31: user83@example.com
A32: EMP1030 | C32: Marketing | E32: 92259 | G32: 1 | H32: Unknown | I32: user109@example.com
A33: EMP1031 | B33: Eve Adams | C33: HR | D33: Germany | E33: 92299 | F33: 42225 | G33: 3 | H33: Male | I33: user143@example.com
A34: EMP1032 | B34: Sam Wilson | C34: HR | E34: 95586 | F34: 42232 | G34: 3 | H34: Other | I34: user190@example.com
A35: EMP1033 | B35: Chris Lee | D35: USA | E35: 95367 | F35: 42239 | H35: Male | I35: user136@example.com
A36: EMP1034 | B36: John Doe | C36: Sales | D36: Australia | E36: 79549 | F36: 42246 | G36: 3 | I36: user198@example.com
A37: EMP1035 | B37: Alice Brown | D37: UK | E37: 54463 | F37: 42253 | G37: 4 | H37: Male | I37: invalid_email
A38: EMP1036 | B38: Alice Brown | C38: IT | D38: USA | E38: 89781 | F38: 42260 | H38: Female | I38: user31@example.com
A39: EMP1037 | B39: Alice Brown | C39: HR | E39: 64796 | F39: 42267 | H39: Other | I39: user98@example.com
A40: EMP1038 | B40: John Doe | C40: Marketing | D40: UK | E40: 52093 | F40: 42274 | G40: 5 | I40: user154@example.com
...

Sheet Day-3 Observations
I3: Day 3 – Basic Excel Formulas (Part 1)
H4: No. | I4: Observation
H5: 1 | I5: The SUM function was used to calculate the total Salary and Performance Rating.
H6: 2 | I6: The AVERAGE function was used to calculate the average Salary and Performance Rating.
H7: 3 | I7: The MIN and MAX functions were used to identify the minimum and maximum values.
H8: 4 | I8: The COUNT function counted the numeric values in the Salary and Performance Rating columns.

Sheet Day-4 Clean Dataset
A1: Employee ID | B1: Name | C1: Department | D1: Country | E1: Salary | F1: Date of Joining | G1: Performance Rating | H1: Gender | I1: Email | J1: Metric | K1: Salary | L1: Performance Rating | M1: Salary Category | N1: Condition | O1: Count
A2: EMP1000 | C2: Finance | E2: N/A | G2: 2 | H2: Unknown | I2: invalid_email | J2: Total Salary | K2: =SUM(E:E) -> 9411892 | L2: =SUM(G:G) -> 359 | M2: =IF(E2="N/A","N/A",IF(E2>=70000,"High","Low")) -> N/A | N2: Salary >= 70000 | O2: =COUNTIF(E:E,">=70000") -> 63
A3: EMP1001 | B3: Eve Adams | C3: HR | D3: Germany | E3: 54255 | F3: 42015 | G3: 1 | H3: Other | I3: user106@example.com | J3: Average Salary | K3: =AVERAGE(E:E) -> 66280.93 | L3: =AVERAGE(G:G) -> 2.872 | M3: =IF(E3="N/A","N/A",IF(E3>=70000,"High","Low")) -> Low | N3: Performance Rating >= 4 | O3: =COUNTIF(G:G,">=4") -> 42
A4: EMP1002 | B4: Alice Brown | C4: Finance | D4: Germany | E4: 63184 | F4: 42022 | G4: 2 | I4: user176@example.com | J4: Minimum Salary | K4: =MIN(E:E) -> 30280 | L4: =MIN(G:G) -> 1 | M4: =IF(E4="N/A","N/A",IF(E4>=70000,"High","Low")) -> Low | N4: Department = IT | O4: =COUNTIF(C:C,"IT") -> 25
A5: EMP1003 | B5: John Doe | C5: Sales | D5: USA | E5: 94406 | F5: 42029 | G5: 1 | H5: Male | I5: user168@example.com | J5: Maximum Salary | K5: =MAX(E:E) -> 99621 | L5: =MAX(G:G) -> 5 | M5: =IF(E5="N/A","N/A",IF(E5>=70000,"High","Low")) -> High | N5: Total Salary - IT | O5: =SUMIF(C:C,"IT",E:E) -> 1587780
A6: EMP1004 | B6: Jane Smith | C6: Sales | D6: Germany | E6: 64120 | F6: 42036 | G6: 1 | H6: Male | I6: user49@example.com | J6: Count Salary | K6: =COUNT(E:E) -> 142 | L6: =COUNT(G:G) -> 125 | M6: =IF(E6="N/A","N/A",IF(E6>=70000,"High","Low")) -> Low | N6: Average Salary - IT | O6: =AVERAGEIF(C:C,"IT",E:E) -> 66157.5
A7: EMP1005 | B7: Alice Brown | C7: IT | D7: India | E7: 78421 | F7: 42043 | G7: 2 | H7: Female | I7: user24@example.com | M7: =IF(E7="N/A","N/A",IF(E7>=70000,"High","Low")) -> High
A8: EMP1006 | B8: Sam Wilson | C8: Sales | E8: 67721 | F8: 42050 | H8: Male | I8: user168@example.com | M8: =IF(E8="N/A","N/A",IF(E8>=70000,"High","Low")) -> Low
A9: EMP1007 | B9: Chris Lee | C9: Marketing | E9: 35364 | F9: 42057 | G9: 2 | H9: Other | I9: user26@example.com | M9: =IF(E9="N/A","N/A",IF(E9>=70000,"High","Low")) -> Low
A10: EMP1008 | B10: Alice Brown | C10: IT | D10: Germany | E10: 97881 | F10: 42064 | H10: Female | I10: user25@example.com | M10: =IF(E10="N/A","N/A",IF(E10>=70000,"High","Low")) -> High
A11: EMP1009 | B11: Chris Lee | C11: HR | D11: UK | E11: 91846 | F11: 42071 | H11: Male | I11: user153@example.com | M11: =IF(E11="N/A","N/A",IF(E11>=70000,"High","Low")) -> High
A12: EMP1010 | B12: Sam Wilson | C12: Finance | D12: UK | E12: 64247 | F12: 42078 | G12: 1 | H12: Female | I12: user18@example.com | M12: =IF(E12="N/A","N/A",IF(E12>=70000,"High","Low")) -> Low
A13: EMP1011 | B13: Sam Wilson | C13: IT | D13: USA | E13: 91180 | F13: 42085 | G13: 5 | H13: Male | I13: user1@example.com | M13: =IF(E13="N/A","N/A",IF(E13>=70000,"High","Low")) -> High
A14: EMP1012 | B14: Bob Johnson | C14: Sales | E14: 96418 | F14: 42092 | G14: 5 | H14: Male | I14: user106@example.com | M14: =IF(E14="N/A","N/A",IF(E14>=70000,"High","Low")) -> High
A15: EMP1013 | B15: Sam Wilson | D15: India | E15: 62158 | F15: 42099 | G15: 4 | I15: user180@example.com | M15: =IF(E15="N/A","N/A",IF(E15>=70000,"High","Low")) -> Low
A16: EMP1014 | B16: Jane Smith | C16: HR | E16: 59894 | F16: 42106 | G16: 2 | H16: Male | I16: user184@example.com | M16: =IF(E16="N/A","N/A",IF(E16>=70000,"High","Low")) -> Low
A17: EMP1015 | C17: IT | D17: India | E17: 92443 | F17: 42113 | G17: 3 | H17: Other | I17: user3@example.com | M17: =IF(E17="N/A","N/A",IF(E17>=70000,"High","Low")) -> High
A18: EMP1016 | B18: Bob Johnson | D18: Germany | E18: 90271 | F18: 42120 | I18: user64@example.com | M18: =IF(E18="N/A","N/A",IF(E18>=70000,"High","Low")) -> High
A19: EMP1017 | B19: Jane Smith | C19: Finance | D19: Australia | E19: 41341 | F19: 42127 | G19: 1 | H19: Other | I19: user38@example.com | M19: =IF(E19="N/A","N/A",IF(E19>=70000,"High","Low")) -> Low
A20: EMP1018 | B20: Alice Brown | C20: Finance | D20: UK | E20: 73602 | F20: 42134 | I20: user96@example.com | M20: =IF(E20="N/A","N/A",IF(E20>=70000,"High","Low")) -> High
A21: EMP1019 | B21: Eve Adams | D21: India | E21: 67531 | F21: 42141 | G21: 5 | H21: Female | I21: user151@example.com | M21: =IF(E21="N/A","N/A",IF(E21>=70000,"High","Low")) -> Low
A22: EMP1020 | B22: Jane Smith | C22: HR | D22: USA | E22: N/A | F22: 42148 | G22: 2 | H22: Other | I22: user200@example.com | M22: =IF(E22="N/A","N/A",IF(E22>=70000,"High","Low")) -> N/A
A23: EMP1021 | B23: Jane Smith | C23: HR | E23: 98922 | F23: 42155 | G23: 4 | I23: user77@example.com | M23: =IF(E23="N/A","N/A",IF(E23>=70000,"High","Low")) -> High
A24: EMP1022 | B24: Eve Adams | C24: Finance | D24: India | E24: 38333 | F24: 42162 | G24: 5 | I24: user128@example.com | M24: =IF(E24="N/A","N/A",IF(E24>=70000,"High","Low")) -> Low
A25: EMP1023 | B25: Alice Brown | C25: Marketing | D25: UK | E25: 36515 | F25: 42169 | G25: 3 | H25: Male | I25: user149@example.com | M25: =IF(E25="N/A","N/A",IF(E25>=70000,"High","Low")) -> Low
A26: EMP1024 | B26: Sam Wilson | C26: Finance | E26: 91005 | F26: 42176 | G26: 1 | H26: Other | I26: user122@example.com | M26: =IF(E26="N/A","N/A",IF(E26>=70000,"High","Low")) -> High
A27: EMP1025 | B27: Chris Lee | E27: 52272 | F27: 42183 | G27: 3 | I27: user41@example.com | M27: =IF(E27="N/A","N/A",IF(E27>=70000,"High","Low")) -> Low
A28: EMP1026 | B28: Eve Adams | C28: Sales | D28: Germany | E28: 76518 | F28: 42190 | G28: 2 | H28: Female | I28: user68@example.com | M28: =IF(E28="N/A","N/A",IF(E28>=70000,"High","Low")) -> High
A29: EMP1027 | B29: Alice Brown | C29: IT | D29: UK | E29: 41448 | F29: 42197 | G29: 3 | H29: Other | I29: user103@example.com | M29: =IF(E29="N/A","N/A",IF(E29>=70000,"High","Low")) -> Low
A30: EMP1028 | B30: John Doe | C30: HR | D30: UK | E30: 49282 | F30: 42204 | G30: 2 | H30: Female | I30: user135@example.com | M30: =IF(E30="N/A","N/A",IF(E30>=70000,"High","Low")) -> Low
A31: EMP1029 | B31: Bob Johnson | C31: Marketing | D31: UK | E31: 92959 | F31: 42211 | G31: 5 | I31: user83@example.com | M31: =IF(E31="N/A","N/A",IF(E31>=70000,"High","Low")) -> High
A32: EMP1030 | C32: Marketing | E32: 92259 | G32: 1 | H32: Unknown | I32: user109@example.com | M32: =IF(E32="N/A","N/A",IF(E32>=70000,"High","Low")) -> High
A33: EMP1031 | B33: Eve Adams | C33: HR | D33: Germany | E33: 92299 | F33: 42225 | G33: 3 | H33: Male | I33: user143@example.com | M33: =IF(E33="N/A","N/A",IF(E33>=70000,"High","Low")) -> High
A34: EMP1032 | B34: Sam Wilson | C34: HR | E34: 95586 | F34: 42232 | G34: 3 | H34: Other | I34: user190@example.com | M34: =IF(E34="N/A","N/A",IF(E34>=70000,"High","Low")) -> High
A35: EMP1033 | B35: Chris Lee | D35: USA | E35: 95367 | F35: 42239 | H35: Male | I35: user136@example.com | M35: =IF(E35="N/A","N/A",IF(E35>=70000,"High","Low")) -> High
A36: EMP1034 | B36: John Doe | C36: Sales | D36: Australia | E36: 79549 | F36: 42246 | G36: 3 | I36: user198@example.com | M36: =IF(E36="N/A","N/A",IF(E36>=70000,"High","Low")) -> High
A37: EMP1035 | B37: Alice Brown | D37: UK | E37: 54463 | F37: 42253 | G37: 4 | H37: Male | I37: invalid_email | M37: =IF(E37="N/A","N/A",IF(E37>=70000,"High","Low")) -> Low
A38: EMP1036 | B38: Alice Brown | C38: IT | D38: USA | E38: 89781 | F38: 42260 | H38: Female | I38: user31@example.com | M38: =IF(E38="N/A","N/A",IF(E38>=70000,"High","Low")) -> High
A39: EMP1037 | B39: Alice Brown | C39: HR | E39: 64796 | F39: 42267 | H39: Other | I39: user98@example.com | M39: =IF(E39="N/A","N/A",IF(E39>=70000,"High","Low")) -> Low
A40: EMP1038 | B40: John Doe | C40: Marketing | D40: UK | E40: 52093 | F40: 42274 | G40: 5 | I40: user154@example.com | M40: =IF(E40="N/A","N/A",IF(E40>=70000,"High","Low")) -> Low
...

Sheet Day-4 Observations
I3: Day 4 – Basic Excel Formulas (Part 2)
H4: No | I4: Observation
H5: 1 | I5: The IF function was used to categorize employees based on their salary.
H6: 2 | I6: The COUNTIF function was used to count employees based on specific conditions.
H7: 3 | I7: The SUMIF function was used to calculate the total salary for employees in the IT department.
H8: 4 | I8: The AVERAGEIF function was used to calculate the average salary for employees in the IT department.

Sheet Day-5 Clean Dataset
A1: Employee ID | B1: Name | C1: Department | D1: Country | E1: Salary | F1: Date of Joining | G1: Performance Rating | H1: Gender | I1: Email | J1: Metric | K1: Salary | L1: Performance Rating | M1: Salary Category | N1: Condition | O1: Count | P1: First 3 Characters | Q1: Last 3 Characters | R1: Middle Characters | S1: Uppercase Name | T1: Lowercase Department | U1: Proper Department
A2: EMP1000 | C2: Finance | E2: N/A | G2: 2 | H2: Unknown | I2: invalid_email | J2: Total Salary | K2: =SUM(E:E) -> 9411892 | L2: =SUM(G:G) -> 359 | M2: =IF(E2="N/A","N/A",IF(E2>=70000,"High","Low")) -> N/A | N2: Salary >= 70000 | O2: =COUNTIF(E:E,">=70000") -> 63 | P2: =LEFT(B2,3) | Q2: =RIGHT(B2,3) | R2: =MID(B2,3,4) | S2: =UPPER(B2) | T2: =LOWER(C2) -> finance | U2: =PROPER(C2) -> Finance
A3: EMP1001 | B3: Eve Adams | C3: HR | D3: Germany | E3: 54255 | F3: 42015 | G3: 1 | H3: Other | I3: user106@example.com | J3: Average Salary | K3: =AVERAGE(E:E) -> 66280.93 | L3: =AVERAGE(G:G) -> 2.872 | M3: =IF(E3="N/A","N/A",IF(E3>=70000,"High","Low")) -> Low | N3: Performance Rating >= 4 | O3: =COUNTIF(G:G,">=4") -> 42 | P3: =LEFT(B3,3) -> Eve | Q3: =RIGHT(B3,3) -> ams | R3: =MID(B3,3,4) -> e Ad | S3: =UPPER(B3) -> EVE ADAMS | T3: =LOWER(C3) -> hr | U3: =PROPER(C3) -> Hr
A4: EMP1002 | B4: Alice Brown | C4: Finance | D4: Germany | E4: 63184 | F4: 42022 | G4: 2 | I4: user176@example.com | J4: Minimum Salary | K4: =MIN(E:E) -> 30280 | L4: =MIN(G:G) -> 1 | M4: =IF(E4="N/A","N/A",IF(E4>=70000,"High","Low")) -> Low | N4: Department = IT | O4: =COUNTIF(C:C,"IT") -> 25 | P4: =LEFT(B4,3) -> Ali | Q4: =RIGHT(B4,3) -> own | R4: =MID(B4,3,4) -> ice | S4: =UPPER(B4) -> ALICE BROWN | T4: =LOWER(C4) -> finance | U4: =PROPER(C4) -> Finance
A5: EMP1003 | B5: John Doe | C5: Sales | D5: USA | E5: 94406 | F5: 42029 | G5: 1 | H5: Male | I5: user168@example.com | J5: Maximum Salary | K5: =MAX(E:E) -> 99621 | L5: =MAX(G:G) -> 5 | M5: =IF(E5="N/A","N/A",IF(E5>=70000,"High","Low")) -> High | N5: Total Salary - IT | O5: =SUMIF(C:C,"IT",E:E) -> 1587780 | P5: =LEFT(B5,3) -> Joh | Q5: =RIGHT(B5,3) -> Doe | R5: =MID(B5,3,4) -> hn D | S5: =UPPER(B5) -> JOHN DOE | T5: =LOWER(C5) -> sales | U5: =PROPER(C5) -> Sales
A6: EMP1004 | B6: Jane Smith | C6: Sales | D6: Germany | E6: 64120 | F6: 42036 | G6: 1 | H6: Male | I6: user49@example.com | J6: Count Salary | K6: =COUNT(E:E) -> 142 | L6: =COUNT(G:G) -> 125 | M6: =IF(E6="N/A","N/A",IF(E6>=70000,"High","Low")) -> Low | N6: Average Salary - IT | O6: =AVERAGEIF(C:C,"IT",E:E) -> 66157.5 | P6: =LEFT(B6,3) -> Jan | Q6: =RIGHT(B6,3) -> ith | R6: =MID(B6,3,4) -> ne S | S6: =UPPER(B6) -> JANE SMITH | T6: =LOWER(C6) -> sales | U6: =PROPER(C6) -> Sales
A7: EMP1005 | B7: Alice Brown | C7: IT | D7: India | E7: 78421 | F7: 42043 | G7: 2 | H7: Female | I7: user24@example.com | M7: =IF(E7="N/A","N/A",IF(E7>=70000,"High","Low")) -> High | P7: =LEFT(B7,3) -> Ali | Q7: =RIGHT(B7,3) -> own | R7: =MID(B7,3,4) -> ice | S7: =UPPER(B7) -> ALICE BROWN | T7: =LOWER(C7) -> it | U7: =PROPER(C7) -> It
A8: EMP1006 | B8: Sam Wilson | C8: Sales | E8: 67721 | F8: 42050 | H8: Male | I8: user168@example.com | M8: =IF(E8="N/A","N/A",IF(E8>=70000,"High","Low")) -> Low | P8: =LEFT(B8,3) -> Sam | Q8: =RIGHT(B8,3) -> son | R8: =MID(B8,3,4) -> m Wi | S8: =UPPER(B8) -> SAM WILSON | T8: =LOWER(C8) -> sales | U8: =PROPER(C8) -> Sales
A9: EMP1007 | B9: Chris Lee | C9: Marketing | E9: 35364 | F9: 42057 | G9: 2 | H9: Other | I9: user26@example.com | M9: =IF(E9="N/A","N/A",IF(E9>=70000,"High","Low")) -> Low | P9: =LEFT(B9,3) -> Chr | Q9: =RIGHT(B9,3) -> Lee | R9: =MID(B9,3,4) -> ris | S9: =UPPER(B9) -> CHRIS LEE | T9: =LOWER(C9) -> marketing | U9: =PROPER(C9) -> Marketing
A10: EMP1008 | B10: Alice Brown | C10: IT | D10: Germany | E10: 97881 | F10: 42064 | H10: Female | I10: user25@example.com | M10: =IF(E10="N/A","N/A",IF(E10>=70000,"High","Low")) -> High | P10: =LEFT(B10,3) -> Ali | Q10: =RIGHT(B10,3) -> own | R10: =MID(B10,3,4) -> ice | S10: =UPPER(B10) -> ALICE BROWN | T10: =LOWER(C10) -> it | U10: =PROPER(C10) -> It
A11: EMP1009 | B11: Chris Lee | C11: HR | D11: UK | E11: 91846 | F11: 42071 | H11: Male | I11: user153@example.com | M11: =IF(E11="N/A","N/A",IF(E11>=70000,"High","Low")) -> High | P11: =LEFT(B11,3) -> Chr | Q11: =RIGHT(B11,3) -> Lee | R11: =MID(B11,3,4) -> ris | S11: =UPPER(B11) -> CHRIS LEE | T11: =LOWER(C11) -> hr | U11: =PROPER(C11) -> Hr
A12: EMP1010 | B12: Sam Wilson | C12: Finance | D12: UK | E12: 64247 | F12: 42078 | G12: 1 | H12: Female | I12: user18@example.com | M12: =IF(E12="N/A","N/A",IF(E12>=70000,"High","Low")) -> Low | P12: =LEFT(B12,3) -> Sam | Q12: =RIGHT(B12,3) -> son | R12: =MID(B12,3,4) -> m Wi | S12: =UPPER(B12) -> SAM WILSON | T12: =LOWER(C12) -> finance | U12: =PROPER(C12) -> Finance
A13: EMP1011 | B13: Sam Wilson | C13: IT | D13: USA | E13: 91180 | F13: 42085 | G13: 5 | H13: Male | I13: user1@example.com | M13: =IF(E13="N/A","N/A",IF(E13>=70000,"High","Low")) -> High | P13: =LEFT(B13,3) -> Sam | Q13: =RIGHT(B13,3) -> son | R13: =MID(B13,3,4) -> m Wi | S13: =UPPER(B13) -> SAM WILSON | T13: =LOWER(C13) -> it | U13: =PROPER(C13) -> It
A14: EMP1012 | B14: Bob Johnson | C14: Sales | E14: 96418 | F14: 42092 | G14: 5 | H14: Male | I14: user106@example.com | M14: =IF(E14="N/A","N/A",IF(E14>=70000,"High","Low")) -> High | P14: =LEFT(B14,3) -> Bob | Q14: =RIGHT(B14,3) -> son | R14: =MID(B14,3,4) -> b Jo | S14: =UPPER(B14) -> BOB JOHNSON | T14: =LOWER(C14) -> sales | U14: =PROPER(C14) -> Sales
A15: EMP1013 | B15: Sam Wilson | D15: India | E15: 62158 | F15: 42099 | G15: 4 | I15: user180@example.com | M15: =IF(E15="N/A","N/A",IF(E15>=70000,"High","Low")) -> Low | P15: =LEFT(B15,3) -> Sam | Q15: =RIGHT(B15,3) -> son | R15: =MID(B15,3,4) -> m Wi | S15: =UPPER(B15) -> SAM WILSON | T15: =LOWER(C15) | U15: =PROPER(C15)
A16: EMP1014 | B16: Jane Smith | C16: HR | E16: 59894 | F16: 42106 | G16: 2 | H16: Male | I16: user184@example.com | M16: =IF(E16="N/A","N/A",IF(E16>=70000,"High","Low")) -> Low | P16: =LEFT(B16,3) -> Jan | Q16: =RIGHT(B16,3) -> ith | R16: =MID(B16,3,4) -> ne S | S16: =UPPER(B16) -> JANE SMITH | T16: =LOWER(C16) -> hr | U16: =PROPER(C16) -> Hr
A17: EMP1015 | C17: IT | D17: India | E17: 92443 | F17: 42113 | G17: 3 | H17: Other | I17: user3@example.com | M17: =IF(E17="N/A","N/A",IF(E17>=70000,"High","Low")) -> High | P17: =LEFT(B17,3) | Q17: =RIGHT(B17,3) | R17: =MID(B17,3,4) | S17: =UPPER(B17) | T17: =LOWER(C17) -> it | U17: =PROPER(C17) -> It
A18: EMP1016 | B18: Bob Johnson | D18: Germany | E18: 90271 | F18: 42120 | I18: user64@example.com | M18: =IF(E18="N/A","N/A",IF(E18>=70000,"High","Low")) -> High | P18: =LEFT(B18,3) -> Bob | Q18: =RIGHT(B18,3) -> son | R18: =MID(B18,3,4) -> b Jo | S18: =UPPER(B18) -> BOB JOHNSON | T18: =LOWER(C18) | U18: =PROPER(C18)
A19: EMP1017 | B19: Jane Smith | C19: Finance | D19: Australia | E19: 41341 | F19: 42127 | G19: 1 | H19: Other | I19: user38@example.com | M19: =IF(E19="N/A","N/A",IF(E19>=70000,"High","Low")) -> Low | P19: =LEFT(B19,3) -> Jan | Q19: =RIGHT(B19,3) -> ith | R19: =MID(B19,3,4) -> ne S | S19: =UPPER(B19) -> JANE SMITH | T19: =LOWER(C19) -> finance | U19: =PROPER(C19) -> Finance
A20: EMP1018 | B20: Alice Brown | C20: Finance | D20: UK | E20: 73602 | F20: 42134 | I20: user96@example.com | M20: =IF(E20="N/A","N/A",IF(E20>=70000,"High","Low")) -> High | P20: =LEFT(B20,3) -> Ali | Q20: =RIGHT(B20,3) -> own | R20: =MID(B20,3,4) -> ice | S20: =UPPER(B20) -> ALICE BROWN | T20: =LOWER(C20) -> finance | U20: =PROPER(C20) -> Finance
A21: EMP1019 | B21: Eve Adams | D21: India | E21: 67531 | F21: 42141 | G21: 5 | H21: Female | I21: user151@example.com | M21: =IF(E21="N/A","N/A",IF(E21>=70000,"High","Low")) -> Low | P21: =LEFT(B21,3) -> Eve | Q21: =RIGHT(B21,3) -> ams | R21: =MID(B21,3,4) -> e Ad | S21: =UPPER(B21) -> EVE ADAMS | T21: =LOWER(C21) | U21: =PROPER(C21)
A22: EMP1020 | B22: Jane Smith | C22: HR | D22: USA | E22: N/A | F22: 42148 | G22: 2 | H22: Other | I22: user200@example.com | M22: =IF(E22="N/A","N/A",IF(E22>=70000,"High","Low")) -> N/A | P22: =LEFT(B22,3) -> Jan | Q22: =RIGHT(B22,3) -> ith | R22: =MID(B22,3,4) -> ne S | S22: =UPPER(B22) -> JANE SMITH | T22: =LOWER(C22) -> hr | U22: =PROPER(C22) -> Hr
A23: EMP1021 | B23: Jane Smith | C23: HR | E23: 98922 | F23: 42155 | G23: 4 | I23: user77@example.com | M23: =IF(E23="N/A","N/A",IF(E23>=70000,"High","Low")) -> High | P23: =LEFT(B23,3) -> Jan | Q23: =RIGHT(B23,3) -> ith | R23: =MID(B23,3,4) -> ne S | S23: =UPPER(B23) -> JANE SMITH | T23: =LOWER(C23) -> hr | U23: =PROPER(C23) -> Hr
A24: EMP1022 | B24: Eve Adams | C24: Finance | D24: India | E24: 38333 | F24: 42162 | G24: 5 | I24: user128@example.com | M24: =IF(E24="N/A","N/A",IF(E24>=70000,"High","Low")) -> Low | P24: =LEFT(B24,3) -> Eve | Q24: =RIGHT(B24,3) -> ams | R24: =MID(B24,3,4) -> e Ad | S24: =UPPER(B24) -> EVE ADAMS | T24: =LOWER(C24) -> finance | U24: =PROPER(C24) -> Finance
A25: EMP1023 | B25: Alice Brown | C25: Marketing | D25: UK | E25: 36515 | F25: 42169 | G25: 3 | H25: Male | I25: user149@example.com | M25: =IF(E25="N/A","N/A",IF(E25>=70000,"High","Low")) -> Low | P25: =LEFT(B25,3) -> Ali | Q25: =RIGHT(B25,3) -> own | R25: =MID(B25,3,4) -> ice | S25: =UPPER(B25) -> ALICE BROWN | T25: =LOWER(C25) -> marketing | U25: =PROPER(C25) -> Marketing
A26: EMP1024 | B26: Sam Wilson | C26: Finance | E26: 91005 | F26: 42176 | G26: 1 | H26: Other | I26: user122@example.com | M26: =IF(E26="N/A","N/A",IF(E26>=70000,"High","Low")) -> High | P26: =LEFT(B26,3) -> Sam | Q26: =RIGHT(B26,3) -> son | R26: =MID(B26,3,4) -> m Wi | S26: =UPPER(B26) -> SAM WILSON | T26: =LOWER(C26) -> finance | U26: =PROPER(C26) -> Finance
A27: EMP1025 | B27: Chris Lee | E27: 52272 | F27: 42183 | G27: 3 | I27: user41@example.com | M27: =IF(E27="N/A","N/A",IF(E27>=70000,"High","Low")) -> Low | P27: =LEFT(B27,3) -> Chr | Q27: =RIGHT(B27,3) -> Lee | R27: =MID(B27,3,4) -> ris | S27: =UPPER(B27) -> CHRIS LEE | T27: =LOWER(C27) | U27: =PROPER(C27)
A28: EMP1026 | B28: Eve Adams | C28: Sales | D28: Germany | E28: 76518 | F28: 42190 | G28: 2 | H28: Female | I28: user68@example.com | M28: =IF(E28="N/A","N/A",IF(E28>=70000,"High","Low")) -> High | P28: =LEFT(B28,3) -> Eve | Q28: =RIGHT(B28,3) -> ams | R28: =MID(B28,3,4) -> e Ad | S28: =UPPER(B28) -> EVE ADAMS | T28: =LOWER(C28) -> sales | U28: =PROPER(C28) -> Sales
A29: EMP1027 | B29: Alice Brown | C29: IT | D29: UK | E29: 41448 | F29: 42197 | G29: 3 | H29: Other | I29: user103@example.com | M29: =IF(E29="N/A","N/A",IF(E29>=70000,"High","Low")) -> Low | P29: =LEFT(B29,3) -> Ali | Q29: =RIGHT(B29,3) -> own | R29: =MID(B29,3,4) -> ice | S29: =UPPER(B29) -> ALICE BROWN | T29: =LOWER(C29) -> it | U29: =PROPER(C29) -> It
A30: EMP1028 | B30: John Doe | C30: HR | D30: UK | E30: 49282 | F30: 42204 | G30: 2 | H30: Female | I30: user135@example.com | M30: =IF(E30="N/A","N/A",IF(E30>=70000,"High","Low")) -> Low | P30: =LEFT(B30,3) -> Joh | Q30: =RIGHT(B30,3) -> Doe | R30: =MID(B30,3,4) -> hn D | S30: =UPPER(B30) -> JOHN DOE | T30: =LOWER(C30) -> hr | U30: =PROPER(C30) -> Hr
A31: EMP1029 | B31: Bob Johnson | C31: Marketing | D31: UK | E31: 92959 | F31: 42211 | G31: 5 | I31: user83@example.com | M31: =IF(E31="N/A","N/A",IF(E31>=70000,"High","Low")) -> High | P31: =LEFT(B31,3) -> Bob | Q31: =RIGHT(B31,3) -> son | R31: =MID(B31,3,4) -> b Jo | S31: =UPPER(B31) -> BOB JOHNSON | T31: =LOWER(C31) -> marketing | U31: =PROPER(C31) -> Marketing
A32: EMP1030 | C32: Marketing | E32: 92259 | G32: 1 | H32: Unknown | I32: user109@example.com | M32: =IF(E32="N/A","N/A",IF(E32>=70000,"High","Low")) -> High | P32: =LEFT(B32,3) | Q32: =RIGHT(B32,3) | R32: =MID(B32,3,4) | S32: =UPPER(B32) | T32: =LOWER(C32) -> marketing | U32: =PROPER(C32) -> Marketing
A33: EMP1031 | B33: Eve Adams | C33: HR | D33: Germany | E33: 92299 | F33: 42225 | G33: 3 | H33: Male | I33: user143@example.com | M33: =IF(E33="N/A","N/A",IF(E33>=70000,"High","Low")) -> High | P33: =LEFT(B33,3) -> Eve | Q33: =RIGHT(B33,3) -> ams | R33: =MID(B33,3,4) -> e Ad | S33: =UPPER(B33) -> EVE ADAMS | T33: =LOWER(C33) -> hr | U33: =PROPER(C33) -> Hr
A34: EMP1032 | B34: Sam Wilson | C34: HR | E34: 95586 | F34: 42232 | G34: 3 | H34: Other | I34: user190@example.com | M34: =IF(E34="N/A","N/A",IF(E34>=70000,"High","Low")) -> High | P34: =LEFT(B34,3) -> Sam | Q34: =RIGHT(B34,3) -> son | R34: =MID(B34,3,4) -> m Wi | S34: =UPPER(B34) -> SAM WILSON | T34: =LOWER(C34) -> hr | U34: =PROPER(C34) -> Hr
A35: EMP1033 | B35: Chris Lee | D35: USA | E35: 95367 | F35: 42239 | H35: Male | I35: user136@example.com | M35: =IF(E35="N/A","N/A",IF(E35>=70000,"High","Low")) -> High | P35: =LEFT(B35,3) -> Chr | Q35: =RIGHT(B35,3) -> Lee | R35: =MID(B35,3,4) -> ris | S35: =UPPER(B35) -> CHRIS LEE | T35: =LOWER(C35) | U35: =PROPER(C35)
A36: EMP1034 | B36: John Doe | C36: Sales | D36: Australia | E36: 79549 | F36: 42246 | G36: 3 | I36: user198@example.com | M36: =IF(E36="N/A","N/A",IF(E36>=70000,"High","Low")) -> High | P36: =LEFT(B36,3) -> Joh | Q36: =RIGHT(B36,3) -> Doe | R36: =MID(B36,3,4) -> hn D | S36: =UPPER(B36) -> JOHN DOE | T36: =LOWER(C36) -> sales | U36: =PROPER(C36) -> Sales
A37: EMP1035 | B37: Alice Brown | D37: UK | E37: 54463 | F37: 42253 | G37: 4 | H37: Male | I37: invalid_email | M37: =IF(E37="N/A","N/A",IF(E37>=70000,"High","Low")) -> Low | P37: =LEFT(B37,3) -> Ali | Q37: =RIGHT(B37,3) -> own | R37: =MID(B37,3,4) -> ice | S37: =UPPER(B37) -> ALICE BROWN | T37: =LOWER(C37) | U37: =PROPER(C37)
A38: EMP1036 | B38: Alice Brown | C38: IT | D38: USA | E38: 89781 | F38: 42260 | H38: Female | I38: user31@example.com | M38: =IF(E38="N/A","N/A",IF(E38>=70000,"High","Low")) -> High | P38: =LEFT(B38,3) -> Ali | Q38: =RIGHT(B38,3) -> own | R38: =MID(B38,3,4) -> ice | S38: =UPPER(B38) -> ALICE BROWN | T38: =LOWER(C38) -> it | U38: =PROPER(C38) -> It
A39: EMP1037 | B39: Alice Brown | C39: HR | E39: 64796 | F39: 42267 | H39: Other | I39: user98@example.com | M39: =IF(E39="N/A","N/A",IF(E39>=70000,"High","Low")) -> Low | P39: =LEFT(B39,3) -> Ali | Q39: =RIGHT(B39,3) -> own | R39: =MID(B39,3,4) -> ice | S39: =UPPER(B39) -> ALICE BROWN | T39: =LOWER(C39) -> hr | U39: =PROPER(C39) -> Hr
A40: EMP1038 | B40: John Doe | C40: Marketing | D40: UK | E40: 52093 | F40: 42274 | G40: 5 | I40: user154@example.com | M40: =IF(E40="N/A","N/A",IF(E40>=70000,"High","Low")) -> Low | P40: =LEFT(B40,3) -> Joh | Q40: =RIGHT(B40,3) -> Doe | R40: =MID(B40,3,4) -> hn D | S40: =UPPER(B40) -> JOHN DOE | T40: =LOWER(C40) -> marketing | U40: =PROPER(C40) -> Marketing
...

Sheet Day-5 Observations
J4: Day 5 – Text Functions Practice
I5: No. | J5: Observation
I6: 1 | J6: The LEFT function was used to extract characters from the beginning of employee names.
I7: 2 | J7: The RIGHT function was used to extract characters from the end of employee names.
I8: 3 | J8: The MID function was used to extract characters from the middle of employee names.
I9: 4 | J9: The UPPER, LOWER, and PROPER functions were used to format text consistently.

Sheet Day-6 Clean Dataset
A1: Employee ID | B1: Name | C1: Department | D1: Country | E1: Salary | F1: Date of Joining | G1: Performance Rating | H1: Gender | I1: Email | J1: Metric | K1: Salary | L1: Performance Rating | M1: Salary Category | N1: Condition | O1: Count | P1: First 3 Characters | Q1: Last 3 Characters | R1: Middle Characters | S1: Uppercase Name | T1: Lowercase Department | U1: Proper Department
A2: EMP1000 | B2: Unknown | C2: Finance | D2: Unknown | E2: Unknown | F2: Unknown | G2: 2 | H2: Unknown | I2: Unknown | J2: Total Salary | K2: =SUM(E:E) -> 9411892 | L2: =SUM(G:G) -> 359 | M2: =IF(E2="N/A","N/A",IF(E2>=70000,"High","Low")) -> High | N2: Salary >= 70000 | O2: =COUNTIF(E:E,">=70000") -> 63 | P2: =LEFT(B2,3) -> Unk | Q2: =RIGHT(B2,3) -> own | R2: =MID(B2,3,4) -> know | S2: =UPPER(B2) -> UNKNOWN | T2: =LOWER(C2) -> finance | U2: =PROPER(C2) -> Finance
A3: EMP1001 | B3: Eve Adams | C3: HR | D3: Germany | E3: 54255 | F3: 42015 | G3: 1 | H3: Other | I3: user106@example.com | J3: Average Salary | K3: =AVERAGE(E:E) -> 66280.93 | L3: =AVERAGE(G:G) -> 2.872 | M3: =IF(E3="N/A","N/A",IF(E3>=70000,"High","Low")) -> Low | N3: Performance Rating >= 4 | O3: =COUNTIF(G:G,">=4") -> 42 | P3: =LEFT(B3,3) -> Eve | Q3: =RIGHT(B3,3) -> ams | R3: =MID(B3,3,4) -> e Ad | S3: =UPPER(B3) -> EVE ADAMS | T3: =LOWER(C3) -> hr | U3: =PROPER(C3) -> Hr
A4: EMP1002 | B4: Alice Brown | C4: Finance | D4: Germany | E4: 63184 | F4: 42022 | G4: 2 | H4: Unknown | I4: user176@example.com | J4: Minimum Salary | K4: =MIN(E:E) -> 30280 | L4: =MIN(G:G) -> 1 | M4: =IF(E4="N/A","N/A",IF(E4>=70000,"High","Low")) -> Low | N4: Department = IT | O4: =COUNTIF(C:C,"IT") -> 25 | P4: =LEFT(B4,3) -> Ali | Q4: =RIGHT(B4,3) -> own | R4: =MID(B4,3,4) -> ice | S4: =UPPER(B4) -> ALICE BROWN | T4: =LOWER(C4) -> finance | U4: =PROPER(C4) -> Finance
A5: EMP1003 | B5: John Doe | C5: Sales | D5: USA | E5: 94406 | F5: 42029 | G5: 1 | H5: Male | I5: user168@example.com | J5: Maximum Salary | K5: =MAX(E:E) -> 99621 | L5: =MAX(G:G) -> 5 | M5: =IF(E5="N/A","N/A",IF(E5>=70000,"High","Low")) -> High | N5: Total Salary - IT | O5: =SUMIF(C:C,"IT",E:E) -> 1587780 | P5: =LEFT(B5,3) -> Joh | Q5: =RIGHT(B5,3) -> Doe | R5: =MID(B5,3,4) -> hn D | S5: =UPPER(B5) -> JOHN DOE | T5: =LOWER(C5) -> sales | U5: =PROPER(C5) -> Sales
A6: EMP1004 | B6: Jane Smith | C6: Sales | D6: Germany | E6: 64120 | F6: 42036 | G6: 1 | H6: Male | I6: user49@example.com | J6: Count Salary | K6: =COUNT(E:E) -> 142 | L6: =COUNT(G:G) -> 125 | M6: =IF(E6="N/A","N/A",IF(E6>=70000,"High","Low")) -> Low | N6: Average Salary - IT | O6: =AVERAGEIF(C:C,"IT",E:E) -> 66157.5 | P6: =LEFT(B6,3) -> Jan | Q6: =RIGHT(B6,3) -> ith | R6: =MID(B6,3,4) -> ne S | S6: =UPPER(B6) -> JANE SMITH | T6: =LOWER(C6) -> sales | U6: =PROPER(C6) -> Sales
A7: EMP1005 | B7: Alice Brown | C7: IT | D7: India | E7: 78421 | F7: 42043 | G7: 2 | H7: Female | I7: user24@example.com | M7: =IF(E7="N/A","N/A",IF(E7>=70000,"High","Low")) -> High | P7: =LEFT(B7,3) -> Ali | Q7: =RIGHT(B7,3) -> own | R7: =MID(B7,3,4) -> ice | S7: =UPPER(B7) -> ALICE BROWN | T7: =LOWER(C7) -> it | U7: =PROPER(C7) -> It
A8: EMP1006 | B8: Sam Wilson | C8: Sales | D8: Unknown | E8: 67721 | F8: 42050 | G8: Unknown | H8: Male | I8: user168@example.com | M8: =IF(E8="N/A","N/A",IF(E8>=70000,"High","Low")) -> Low | P8: =LEFT(B8,3) -> Sam | Q8: =RIGHT(B8,3) -> son | R8: =MID(B8,3,4) -> m Wi | S8: =UPPER(B8) -> SAM WILSON | T8: =LOWER(C8) -> sales | U8: =PROPER(C8) -> Sales
A9: EMP1007 | B9: Chris Lee | C9: Marketing | D9: Unknown | E9: 35364 | F9: 42057 | G9: 2 | H9: Other | I9: user26@example.com | M9: =IF(E9="N/A","N/A",IF(E9>=70000,"High","Low")) -> Low | P9: =LEFT(B9,3) -> Chr | Q9: =RIGHT(B9,3) -> Lee | R9: =MID(B9,3,4) -> ris | S9: =UPPER(B9) -> CHRIS LEE | T9: =LOWER(C9) -> marketing | U9: =PROPER(C9) -> Marketing
A10: EMP1008 | B10: Alice Brown | C10: IT | D10: Germany | E10: 97881 | F10: 42064 | G10: Unknown | H10: Female | I10: user25@example.com | M10: =IF(E10="N/A","N/A",IF(E10>=70000,"High","Low")) -> High | P10: =LEFT(B10,3) -> Ali | Q10: =RIGHT(B10,3) -> own | R10: =MID(B10,3,4) -> ice | S10: =UPPER(B10) -> ALICE BROWN | T10: =LOWER(C10) -> it | U10: =PROPER(C10) -> It
A11: EMP1009 | B11: Chris Lee | C11: HR | D11: UK | E11: 91846 | F11: 42071 | G11: Unknown | H11: Male | I11: user153@example.com | M11: =IF(E11="N/A","N/A",IF(E11>=70000,"High","Low")) -> High | P11: =LEFT(B11,3) -> Chr | Q11: =RIGHT(B11,3) -> Lee | R11: =MID(B11,3,4) -> ris | S11: =UPPER(B11) -> CHRIS LEE | T11: =LOWER(C11) -> hr | U11: =PROPER(C11) -> Hr
A12: EMP1010 | B12: Sam Wilson | C12: Finance | D12: UK | E12: 64247 | F12: 42078 | G12: 1 | H12: Female | I12: user18@example.com | M12: =IF(E12="N/A","N/A",IF(E12>=70000,"High","Low")) -> Low | P12: =LEFT(B12,3) -> Sam | Q12: =RIGHT(B12,3) -> son | R12: =MID(B12,3,4) -> m Wi | S12: =UPPER(B12) -> SAM WILSON | T12: =LOWER(C12) -> finance | U12: =PROPER(C12) -> Finance
A13: EMP1011 | B13: Sam Wilson | C13: IT | D13: USA | E13: 91180 | F13: 42085 | G13: 5 | H13: Male | I13: user1@example.com | M13: =IF(E13="N/A","N/A",IF(E13>=70000,"High","Low")) -> High | P13: =LEFT(B13,3) -> Sam | Q13: =RIGHT(B13,3) -> son | R13: =MID(B13,3,4) -> m Wi | S13: =UPPER(B13) -> SAM WILSON | T13: =LOWER(C13) -> it | U13: =PROPER(C13) -> It
A14: EMP1012 | B14: Bob Johnson | C14: Sales | D14: Unknown | E14: 96418 | F14: 42092 | G14: 5 | H14: Male | I14: user106@example.com | M14: =IF(E14="N/A","N/A",IF(E14>=70000,"High","Low")) -> High | P14: =LEFT(B14,3) -> Bob | Q14: =RIGHT(B14,3) -> son | R14: =MID(B14,3,4) -> b Jo | S14: =UPPER(B14) -> BOB JOHNSON | T14: =LOWER(C14) -> sales | U14: =PROPER(C14) -> Sales
A15: EMP1013 | B15: Sam Wilson | C15: Unknown | D15: India | E15: 62158 | F15: 42099 | G15: 4 | H15: Unknown | I15: user180@example.com | M15: =IF(E15="N/A","N/A",IF(E15>=70000,"High","Low")) -> Low | P15: =LEFT(B15,3) -> Sam | Q15: =RIGHT(B15,3) -> son | R15: =MID(B15,3,4) -> m Wi | S15: =UPPER(B15) -> SAM WILSON | T15: =LOWER(C15) -> unknown | U15: =PROPER(C15) -> Unknown
A16: EMP1014 | B16: Jane Smith | C16: HR | D16: Unknown | E16: 59894 | F16: 42106 | G16: 2 | H16: Male | I16: user184@example.com | M16: =IF(E16="N/A","N/A",IF(E16>=70000,"High","Low")) -> Low | P16: =LEFT(B16,3) -> Jan | Q16: =RIGHT(B16,3) -> ith | R16: =MID(B16,3,4) -> ne S | S16: =UPPER(B16) -> JANE SMITH | T16: =LOWER(C16) -> hr | U16: =PROPER(C16) -> Hr
A17: EMP1015 | B17: Unknown | C17: IT | D17: India | E17: 92443 | F17: 42113 | G17: 3 | H17: Other | I17: user3@example.com | M17: =IF(E17="N/A","N/A",IF(E17>=70000,"High","Low")) -> High | P17: =LEFT(B17,3) -> Unk | Q17: =RIGHT(B17,3) -> own | R17: =MID(B17,3,4) -> know | S17: =UPPER(B17) -> UNKNOWN | T17: =LOWER(C17) -> it | U17: =PROPER(C17) -> It
A18: EMP1016 | B18: Bob Johnson | C18: Unknown | D18: Germany | E18: 90271 | F18: 42120 | G18: Unknown | H18: Unknown | I18: user64@example.com | M18: =IF(E18="N/A","N/A",IF(E18>=70000,"High","Low")) -> High | P18: =LEFT(B18,3) -> Bob | Q18: =RIGHT(B18,3) -> son | R18: =MID(B18,3,4) -> b Jo | S18: =UPPER(B18) -> BOB JOHNSON | T18: =LOWER(C18) -> unknown | U18: =PROPER(C18) -> Unknown
A19: EMP1017 | B19: Jane Smith | C19: Finance | D19: Australia | E19: 41341 | F19: 42127 | G19: 1 | H19: Other | I19: user38@example.com | M19: =IF(E19="N/A","N/A",IF(E19>=70000,"High","Low")) -> Low | P19: =LEFT(B19,3) -> Jan | Q19: =RIGHT(B19,3) -> ith | R19: =MID(B19,3,4) -> ne S | S19: =UPPER(B19) -> JANE SMITH | T19: =LOWER(C19) -> finance | U19: =PROPER(C19) -> Finance
A20: EMP1018 | B20: Alice Brown | C20: Finance | D20: UK | E20: 73602 | F20: 42134 | G20: Unknown | H20: Unknown | I20: user96@example.com | M20: =IF(E20="N/A","N/A",IF(E20>=70000,"High","Low")) -> High | P20: =LEFT(B20,3) -> Ali | Q20: =RIGHT(B20,3) -> own | R20: =MID(B20,3,4) -> ice | S20: =UPPER(B20) -> ALICE BROWN | T20: =LOWER(C20) -> finance | U20: =PROPER(C20) -> Finance
A21: EMP1019 | B21: Eve Adams | C21: Unknown | D21: India | E21: 67531 | F21: 42141 | G21: 5 | H21: Female | I21: user151@example.com | M21: =IF(E21="N/A","N/A",IF(E21>=70000,"High","Low")) -> Low | P21: =LEFT(B21,3) -> Eve | Q21: =RIGHT(B21,3) -> ams | R21: =MID(B21,3,4) -> e Ad | S21: =UPPER(B21) -> EVE ADAMS | T21: =LOWER(C21) -> unknown | U21: =PROPER(C21) -> Unknown
A22: EMP1020 | B22: Jane Smith | C22: HR | D22: USA | E22: Unknown | F22: 42148 | G22: 2 | H22: Other | I22: user200@example.com | M22: =IF(E22="N/A","N/A",IF(E22>=70000,"High","Low")) -> High | P22: =LEFT(B22,3) -> Jan | Q22: =RIGHT(B22,3) -> ith | R22: =MID(B22,3,4) -> ne S | S22: =UPPER(B22) -> JANE SMITH | T22: =LOWER(C22) -> hr | U22: =PROPER(C22) -> Hr
A23: EMP1021 | B23: Jane Smith | C23: HR | D23: Unknown | E23: 98922 | F23: 42155 | G23: 4 | H23: Unknown | I23: user77@example.com | M23: =IF(E23="N/A","N/A",IF(E23>=70000,"High","Low")) -> High | P23: =LEFT(B23,3) -> Jan | Q23: =RIGHT(B23,3) -> ith | R23: =MID(B23,3,4) -> ne S | S23: =UPPER(B23) -> JANE SMITH | T23: =LOWER(C23) -> hr | U23: =PROPER(C23) -> Hr
A24: EMP1022 | B24: Eve Adams | C24: Finance | D24: India | E24: 38333 | F24: 42162 | G24: 5 | H24: Unknown | I24: user128@example.com | M24: =IF(E24="N/A","N/A",IF(E24>=70000,"High","Low")) -> Low | P24: =LEFT(B24,3) -> Eve | Q24: =RIGHT(B24,3) -> ams | R24: =MID(B24,3,4) -> e Ad | S24: =UPPER(B24) -> EVE ADAMS | T24: =LOWER(C24) -> finance | U24: =PROPER(C24) -> Finance
A25: EMP1023 | B25: Alice Brown | C25: Marketing | D25: UK | E25: 36515 | F25: 42169 | G25: 3 | H25: Male | I25: user149@example.com | M25: =IF(E25="N/A","N/A",IF(E25>=70000,"High","Low")) -> Low | P25: =LEFT(B25,3) -> Ali | Q25: =RIGHT(B25,3) -> own | R25: =MID(B25,3,4) -> ice | S25: =UPPER(B25) -> ALICE BROWN | T25: =LOWER(C25) -> marketing | U25: =PROPER(C25) -> Marketing
A26: EMP1024 | B26: Sam Wilson | C26: Finance | D26: Unknown | E26: 91005 | F26: 42176 | G26: 1 | H26: Other | I26: user122@example.com | M26: =IF(E26="N/A","N/A",IF(E26>=70000,"High","Low")) -> High | P26: =LEFT(B26,3) -> Sam | Q26: =RIGHT(B26,3) -> son | R26: =MID(B26,3,4) -> m Wi | S26: =UPPER(B26) -> SAM WILSON | T26: =LOWER(C26) -> finance | U26: =PROPER(C26) -> Finance
A27: EMP1025 | B27: Chris Lee | C27: Unknown | D27: Unknown | E27: 52272 | F27: 42183 | G27: 3 | H27: Unknown | I27: user41@example.com | M27: =IF(E27="N/A","N/A",IF(E27>=70000,"High","Low")) -> Low | P27: =LEFT(B27,3) -> Chr | Q27: =RIGHT(B27,3) -> Lee | R27: =MID(B27,3,4) -> ris | S27: =UPPER(B27) -> CHRIS LEE | T27: =LOWER(C27) -> unknown | U27: =PROPER(C27) -> Unknown
A28: EMP1026 | B28: Eve Adams | C28: Sales | D28: Germany | E28: 76518 | F28: 42190 | G28: 2 | H28: Female | I28: user68@example.com | M28: =IF(E28="N/A","N/A",IF(E28>=70000,"High","Low")) -> High | P28: =LEFT(B28,3) -> Eve | Q28: =RIGHT(B28,3) -> ams | R28: =MID(B28,3,4) -> e Ad | S28: =UPPER(B28) -> EVE ADAMS | T28: =LOWER(C28) -> sales | U28: =PROPER(C28) -> Sales
A29: EMP1027 | B29: Alice Brown | C29: IT | D29: UK | E29: 41448 | F29: 42197 | G29: 3 | H29: Other | I29: user103@example.com | M29: =IF(E29="N/A","N/A",IF(E29>=70000,"High","Low")) -> Low | P29: =LEFT(B29,3) -> Ali | Q29: =RIGHT(B29,3) -> own | R29: =MID(B29,3,4) -> ice | S29: =UPPER(B29) -> ALICE BROWN | T29: =LOWER(C29) -> it | U29: =PROPER(C29) -> It
A30: EMP1028 | B30: John Doe | C30: HR | D30: UK | E30: 49282 | F30: 42204 | G30: 2 | H30: Female | I30: user135@example.com | M30: =IF(E30="N/A","N/A",IF(E30>=70000,"High","Low")) -> Low | P30: =LEFT(B30,3) -> Joh | Q30: =RIGHT(B30,3) -> Doe | R30: =MID(B30,3,4) -> hn D | S30: =UPPER(B30) -> JOHN DOE | T30: =LOWER(C30) -> hr | U30: =PROPER(C30) -> Hr
A31: EMP1029 | B31: Bob Johnson | C31: Marketing | D31: UK | E31: 92959 | F31: 42211 | G31: 5 | H31: Unknown | I31: user83@example.com | M31: =IF(E31="N/A","N/A",IF(E31>=70000,"High","Low")) -> High | P31: =LEFT(B31,3) -> Bob | Q31: =RIGHT(B31,3) -> son | R31: =MID(B31,3,4) -> b Jo | S31: =UPPER(B31) -> BOB JOHNSON | T31: =LOWER(C31) -> marketing | U31: =PROPER(C31) -> Marketing
A32: EMP1030 | B32: Unknown | C32: Marketing | D32: Unknown | E32: 92259 | F32: Unknown | G32: 1 | H32: Unknown | I32: user109@example.com | M32: =IF(E32="N/A","N/A",IF(E32>=70000,"High","Low")) -> High | P32: =LEFT(B32,3) -> Unk | Q32: =RIGHT(B32,3) -> own | R32: =MID(B32,3,4) -> know | S32: =UPPER(B32) -> UNKNOWN | T32: =LOWER(C32) -> marketing | U32: =PROPER(C32) -> Marketing
A33: EMP1031 | B33: Eve Adams | C33: HR | D33: Germany | E33: 92299 | F33: 42225 | G33: 3 | H33: Male | I33: user143@example.com | M33: =IF(E33="N/A","N/A",IF(E33>=70000,"High","Low")) -> High | P33: =LEFT(B33,3) -> Eve | Q33: =RIGHT(B33,3) -> ams | R33: =MID(B33,3,4) -> e Ad | S33: =UPPER(B33) -> EVE ADAMS | T33: =LOWER(C33) -> hr | U33: =PROPER(C33) -> Hr
A34: EMP1032 | B34: Sam Wilson | C34: HR | D34: Unknown | E34: 95586 | F34: 42232 | G34: 3 | H34: Other | I34: user190@example.com | M34: =IF(E34="N/A","N/A",IF(E34>=70000,"High","Low")) -> High | P34: =LEFT(B34,3) -> Sam | Q34: =RIGHT(B34,3) -> son | R34: =MID(B34,3,4) -> m Wi | S34: =UPPER(B34) -> SAM WILSON | T34: =LOWER(C34) -> hr | U34: =PROPER(C34) -> Hr
A35: EMP1033 | B35: Chris Lee | C35: Unknown | D35: USA | E35: 95367 | F35: 42239 | G35: Unknown | H35: Male | I35: user136@example.com | M35: =IF(E35="N/A","N/A",IF(E35>=70000,"High","Low")) -> High | P35: =LEFT(B35,3) -> Chr | Q35: =RIGHT(B35,3) -> Lee | R35: =MID(B35,3,4) -> ris | S35: =UPPER(B35) -> CHRIS LEE | T35: =LOWER(C35) -> unknown | U35: =PROPER(C35) -> Unknown
A36: EMP1034 | B36: John Doe | C36: Sales | D36: Australia | E36: 79549 | F36: 42246 | G36: 3 | H36: Unknown | I36: user198@example.com | M36: =IF(E36="N/A","N/A",IF(E36>=70000,"High","Low")) -> High | P36: =LEFT(B36,3) -> Joh | Q36: =RIGHT(B36,3) -> Doe | R36: =MID(B36,3,4) -> hn D | S36: =UPPER(B36) -> JOHN DOE | T36: =LOWER(C36) -> sales | U36: =PROPER(C36) -> Sales
A37: EMP1035 | B37: Alice Brown | C37: Unknown | D37: UK | E37: 54463 | F37: 42253 | G37: 4 | H37: Male | I37: Unknown | M37: =IF(E37="N/A","N/A",IF(E37>=70000,"High","Low")) -> Low | P37: =LEFT(B37,3) -> Ali | Q37: =RIGHT(B37,3) -> own | R37: =MID(B37,3,4) -> ice | S37: =UPPER(B37) -> ALICE BROWN | T37: =LOWER(C37) -> unknown | U37: =PROPER(C37) -> Unknown
A38: EMP1036 | B38: Alice Brown | C38: IT | D38: USA | E38: 89781 | F38: 42260 | G38: Unknown | H38: Female | I38: user31@example.com | M38: =IF(E38="N/A","N/A",IF(E38>=70000,"High","Low")) -> High | P38: =LEFT(B38,3) -> Ali | Q38: =RIGHT(B38,3) -> own | R38: =MID(B38,3,4) -> ice | S38: =UPPER(B38) -> ALICE BROWN | T38: =LOWER(C38) -> it | U38: =PROPER(C38) -> It
A39: EMP1037 | B39: Alice Brown | C39: HR | D39: Unknown | E39: 64796 | F39: 42267 | G39: Unknown | H39: Other | I39: user98@example.com | M39: =IF(E39="N/A","N/A",IF(E39>=70000,"High","Low")) -> Low | P39: =LEFT(B39,3) -> Ali | Q39: =RIGHT(B39,3) -> own | R39: =MID(B39,3,4) -> ice | S39: =UPPER(B39) -> ALICE BROWN | T39: =LOWER(C39) -> hr | U39: =PROPER(C39) -> Hr
A40: EMP1038 | B40: John Doe | C40: Marketing | D40: UK | E40: 52093 | F40: 42274 | G40: 5 | H40: Unknown | I40: user154@example.com | M40: =IF(E40="N/A","N/A",IF(E40>=70000,"High","Low")) -> Low | P40: =LEFT(B40,3) -> Joh | Q40: =RIGHT(B40,3) -> Doe | R40: =MID(B40,3,4) -> hn D | S40: =UPPER(B40) -> JOHN DOE | T40: =LOWER(C40) -> marketing | U40: =PROPER(C40) -> Marketing
...

Sheet Day-6 Observations
I4: Day 6 – Data Validation & Cleaning Intro
H5: No. | I5: Observation
H6: 1 | I6: No duplicate records were found in the dataset.
H7: 2 | I7: Blank Name, Department, Country, Date of Joining, Performance Rating, and Gender values were identified and handled using Unknown.
H8: 3 | I8: Missing Salary values represented as N/A were handled using Unknown.
H9: 4 | I9: Invalid Email values were identified and replaced with Unknown.

Sheet Day-7 Clean Dataset
